Workbook

Sheet customer_table
A1: customer_code | B1: custmer_name | C1: customer_type | D1: Column1
A2: Cus001 | B2: Surge Stores | C2: Brick & Mortar
A3: Cus002 | B3: Nomad Stores | C3: Brick & Mortar
A4: Cus003 | B4: Excel Stores | C4: Brick & Mortar
A5: Cus004 | B5: Surface Stores | C5: Brick & Mortar
A6: Cus005 | B6: Premium Stores | C6: Brick & Mortar
A7: Cus006 | B7: Electricalsara Stores | C7: Brick & Mortar
A8: Cus007 | B8: Info Stores | C8: Brick & Mortar
A9: Cus008 | B9: Acclaimed Stores | C9: Brick & Mortar
A10: Cus009 | B10: Electricalsquipo Stores | C10: Brick & Mortar
A11: Cus010 | B11: Atlas Stores | C11: Brick & Mortar
A12: Cus011 | B12: Flawless Stores | C12: Brick & Mortar
A13: Cus012 | B13: Integration Stores | C13: Brick & Mortar
... A39: Cus038 | B39: Leader | C39: E-Commerce

Sheet date_table
A1: date | B1: cy_date | C1: year | D1: month_name | E1: date_yy_mmm
A2: 42887 | B2: 42887 | C2: 2017 | D2: June | E2: 17-Jun_x000D_
A3: 42888 | B3: 42887 | C3: 2017 | D3: June | E3: 17-Jun_x000D_
A4: 42889 | B4: 42887 | C4: 2017 | D4: June | E4: 17-Jun_x000D_
A5: 42890 | B5: 42887 | C5: 2017 | D5: June | E5: 17-Jun_x000D_
A6: 42891 | B6: 42887 | C6: 2017 | D6: June | E6: 17-Jun_x000D_
A7: 42892 | B7: 42887 | C7: 2017 | D7: June | E7: 17-Jun_x000D_
A8: 42893 | B8: 42887 | C8: 2017 | D8: June | E8: 17-Jun_x000D_
A9: 42894 | B9: 42887 | C9: 2017 | D9: June | E9: 17-Jun_x000D_
A10: 42895 | B10: 42887 | C10: 2017 | D10: June | E10: 17-Jun_x000D_
A11: 42896 | B11: 42887 | C11: 2017 | D11: June | E11: 17-Jun_x000D_
A12: 42897 | B12: 42887 | C12: 2017 | D12: June | E12: 17-Jun_x000D_
A13: 42898 | B13: 42887 | C13: 2017 | D13: June | E13: 17-Jun_x000D_
... A1001: 43886 | B1001: 43862 | C1001: 2020 | D1001: February | E1001: 20-Feb_x000D_

Sheet markets_table
A1: markets_code | B1: markets_name | C1: zone
A2: Mark001 | B2: Chennai | C2: South
A3: Mark002 | B3: Mumbai | C3: Central
A4: Mark003 | B4: Ahmedabad | C4: North
A5: Mark004 | B5: Delhi NCR | C5: North
A6: Mark005 | B6: Kanpur | C6: North
A7: Mark006 | B7: Bengaluru | C7: South
A8: Mark007 | B8: Bhopal | C8: Central
A9: Mark008 | B9: Lucknow | C9: North
A10: Mark009 | B10: Patna | C10: North
A11: Mark010 | B11: Kochi | C11: South
A12: Mark011 | B12: Nagpur | C12: Central
... A16: Mark015 | B16: Bhubaneshwar | C16: South
A17: Mark097 | B17: New York
A18: Mark999 | B18: Paris

Sheet product_table
A1: product_code | B1: product_type | C1: Product_type2
A2: Prod001 | B2: Own Brand_x000D_ | C2: =TRIM(CLEAN(product_table[[#This Row],[product_type]])) -> Own Brand
A3: Prod002 | B3: Own Brand_x000D_ | C3: =TRIM(CLEAN(product_table[[#This Row],[product_type]])) -> Own Brand
A4: Prod003 | B4: Own Brand_x000D_ | C4: =TRIM(CLEAN(product_table[[#This Row],[product_type]])) -> Own Brand
A5: Prod004 | B5: Own Brand_x000D_ | C5: =TRIM(CLEAN(product_table[[#This Row],[product_type]])) -> Own Brand
A6: Prod005 | B6: Own Brand_x000D_ | C6: =TRIM(CLEAN(product_table[[#This Row],[product_type]])) -> Own Brand
A7: Prod006 | B7: Own Brand_x000D_ | C7: =TRIM(CLEAN(product_table[[#This Row],[product_type]])) -> Own Brand
A8: Prod007 | B8: Own Brand_x000D_ | C8: =TRIM(CLEAN(product_table[[#This Row],[product_type]])) -> Own Brand
A9: Prod008 | B9: Own Brand_x000D_ | C9: =TRIM(CLEAN(product_table[[#This Row],[product_type]])) -> Own Brand
A10: Prod009 | B10: Own Brand_x000D_ | C10: =TRIM(CLEAN(product_table[[#This Row],[product_type]])) -> Own Brand
A11: Prod010 | B11: Own Brand_x000D_ | C11: =TRIM(CLEAN(product_table[[#This Row],[product_type]])) -> Own Brand
A12: Prod011 | B12: Own Brand_x000D_ | C12: =TRIM(CLEAN(product_table[[#This Row],[product_type]])) -> Own Brand
A13: Prod012 | B13: Own Brand_x000D_ | C13: =TRIM(CLEAN(product_table[[#This Row],[product_type]])) -> Own Brand
... A280: Prod279 | B280: Distribution_x000D_ | C280: =TRIM(CLEAN(product_table[[#This Row],[product_type]])) -> Distribution

Sheet transactions_table
A1: product_code | B1: customer_code | C1: market_code | D1: order_date | E1: sales_qty | F1: sales_amount | G1: currency
A2: Prod001 | B2: Cus001 | C2: Mark001 | D2: 43018 | E2: 100 | F2: 41241 | G2: INR
A3: Prod001 | B3: Cus002 | C3: Mark002 | D3: 43228 | E3: 3 | F3: -1 | G3: INR
A4: Prod002 | B4: Cus003 | C4: Mark003 | D4: 43196 | E4: 1 | F4: 875 | G4: INR
A5: Prod002 | B5: Cus003 | C5: Mark003 | D5: 43201 | E5: 1 | F5: 583 | G5: INR
A6: Prod002 | B6: Cus004 | C6: Mark003 | D6: 43269 | E6: 6 | F6: 7176 | G6: INR
A7: Prod003 | B7: Cus005 | C7: Mark004 | D7: 43059 | E7: 59 | F7: 500 | G7: USD
A8: Prod003 | B8: Cus005 | C8: Mark004 | D8: 43061 | E8: 36 | F8: 250 | G8: USD
A9: Prod003 | B9: Cus005 | C9: Mark004 | D9: 43062 | E9: 39 | F9: 21412 | G9: INR
A10: Prod003 | B10: Cus005 | C10: Mark004 | D10: 43066 | E10: 35 | F10: 19213 | G10: INR
A11: Prod003 | B11: Cus005 | C11: Mark004 | D11: 43067 | E11: 310 | F11: 170185 | G11: INR
A12: Prod003 | B12: Cus005 | C12: Mark004 | D12: 43068 | E12: 184 | F12: 101194 | G12: INR
A13: Prod003 | B13: Cus005 | C13: Mark004 | D13: 43069 | E13: 35 | F13: 19213 | G13: INR
... A1001: Prod018 | B1001: Cus025 | C1001: Mark002 | D1001: 43514 | E1001: 8 | F1001: 17495 | G1001: INR_x000D_

Sheet Master_datatables
A1: product_code | B1: customer_code | C1: market_code | D1: order_date | E1: sales_qty | F1: sales_amount | G1: currency | H1: product_type | I1: markets_name | J1: zone | K1: custmer_name | L1: customer_type | M1: Sales_amount2
A2: Prod001 | B2: Cus001 | C2: Mark001 | D2: 43018 | E2: 100 | F2: 41241 | G2: INR | H2: =VLOOKUP(A2, product_table!$A:$C, 3, 0) -> Own Brand | I2: =VLOOKUP(transactions_table8[[#This Row],[market_code]],markets_table!$A:$B,2,0) -> Chennai | J2: =VLOOKUP(transactions_table8[[#This Row],[market_code]],markets_table!$A:$C,3,0) -> South | K2: =VLOOKUP(transactions_table8[[#This Row],[customer_code]],customer_table!$A:$B,2,0) -> Surge Stores | L2: =VLOOKUP(transactions_table8[[#This Row],[customer_code]],customer_table!$A:$C,3,0) -> Brick & Mortar | M2: =IF(TRIM(CLEAN(transactions_table8[[#This Row],[currency]]))="USD",transactions_table8[[#This Row],[sales_amount]]*83,transactions_table8[[#This Row],[sales_amount]]) -> 41241
A3: Prod002 | B3: Cus003 | C3: Mark003 | D3: 43196 | E3: 1 | F3: 875 | G3: INR | H3: =VLOOKUP(A3, product_table!$A:$C, 3, 0) -> Own Brand | I3: =VLOOKUP(transactions_table8[[#This Row],[market_code]],markets_table!$A:$B,2,0) -> Ahmedabad | J3: =VLOOKUP(transactions_table8[[#This Row],[market_code]],markets_table!$A:$C,3,0) -> North | K3: =VLOOKUP(transactions_table8[[#This Row],[customer_code]],customer_table!$A:$B,2,0) -> Excel Stores | L3: =VLOOKUP(transactions_table8[[#This Row],[customer_code]],customer_table!$A:$C,3,0) -> Brick & Mortar | M3: =IF(TRIM(CLEAN(transactions_table8[[#This Row],[currency]]))="USD",transactions_table8[[#This Row],[sales_amount]]*83,transactions_table8[[#This Row],[sales_amount]]) -> 875
A4: Prod002 | B4: Cus003 | C4: Mark003 | D4: 43201 | E4: 1 | F4: 583 | G4: INR | H4: =VLOOKUP(A4, product_table!$A:$C, 3, 0) -> Own Brand | I4: =VLOOKUP(transactions_table8[[#This Row],[market_code]],markets_table!$A:$B,2,0) -> Ahmedabad | J4: =VLOOKUP(transactions_table8[[#This Row],[market_code]],markets_table!$A:$C,3,0) -> North | K4: =VLOOKUP(transactions_table8[[#This Row],[customer_code]],customer_table!$A:$B,2,0) -> Excel Stores | L4: =VLOOKUP(transactions_table8[[#This Row],[customer_code]],customer_table!$A:$C,3,0) -> Brick & Mortar | M4: =IF(TRIM(CLEAN(transactions_table8[[#This Row],[currency]]))="USD",transactions_table8[[#This Row],[sales_amount]]*83,transactions_table8[[#This Row],[sales_amount]]) -> 583
A5: Prod002 | B5: Cus004 | C5: Mark003 | D5: 43269 | E5: 6 | F5: 7176 | G5: INR | H5: =VLOOKUP(A5, product_table!$A:$C, 3, 0) -> Own Brand | I5: =VLOOKUP(transactions_table8[[#This Row],[market_code]],markets_table!$A:$B,2,0) -> Ahmedabad | J5: =VLOOKUP(transactions_table8[[#This Row],[market_code]],markets_table!$A:$C,3,0) -> North | K5: =VLOOKUP(transactions_table8[[#This Row],[customer_code]],customer_table!$A:$B,2,0) -> Surface Stores | L5: =VLOOKUP(transactions_table8[[#This Row],[customer_code]],customer_table!$A:$C,3,0) -> Brick & Mortar | M5: =IF(TRIM(CLEAN(transactions_table8[[#This Row],[currency]]))="USD",transactions_table8[[#This Row],[sales_amount]]*83,transactions_table8[[#This Row],[sales_amount]]) -> 7176
A6: Prod003 | B6: Cus005 | C6: Mark004 | D6: 43059 | E6: 59 | F6: 500 | G6: USD | H6: =VLOOKUP(A6, product_table!$A:$C, 3, 0) -> Own Brand | I6: =VLOOKUP(transactions_table8[[#This Row],[market_code]],markets_table!$A:$B,2,0) -> Delhi NCR | J6: =VLOOKUP(transactions_table8[[#This Row],[market_code]],markets_table!$A:$C,3,0) -> North | K6: =VLOOKUP(transactions_table8[[#This Row],[customer_code]],customer_table!$A:$B,2,0) -> Premium Stores | L6: =VLOOKUP(transactions_table8[[#This Row],[customer_code]],customer_table!$A:$C,3,0) -> Brick & Mortar | M6: =IF(TRIM(CLEAN(transactions_table8[[#This Row],[currency]]))="USD",transactions_table8[[#This Row],[sales_amount]]*83,transactions_table8[[#This Row],[sales_amount]]) -> 41500
A7: Prod003 | B7: Cus005 | C7: Mark004 | D7: 43061 | E7: 36 | F7: 250 | G7: USD | H7: =VLOOKUP(A7, product_table!$A:$C, 3, 0) -> Own Brand | I7: =VLOOKUP(transactions_table8[[#This Row],[market_code]],markets_table!$A:$B,2,0) -> Delhi NCR | J7: =VLOOKUP(transactions_table8[[#This Row],[market_code]],markets_table!$A:$C,3,0) -> North | K7: =VLOOKUP(transactions_table8[[#This Row],[customer_code]],customer_table!$A:$B,2,0) -> Premium Stores | L7: =VLOOKUP(transactions_table8[[#This Row],[customer_code]],customer_table!$A:$C,3,0) -> Brick & Mortar | M7: =IF(TRIM(CLEAN(transactions_table8[[#This Row],[currency]]))="USD",transactions_table8[[#This Row],[sales_amount]]*83,transactions_table8[[#This Row],[sales_amount]]) -> 20750
A8: Prod003 | B8: Cus005 | C8: Mark004 | D8: 43062 | E8: 39 | F8: 21412 | G8: INR | H8: =VLOOKUP(A8, product_table!$A:$C, 3, 0) -> Own Brand | I8: =VLOOKUP(transactions_table8[[#This Row],[market_code]],markets_table!$A:$B,2,0) -> Delhi NCR | J8: =VLOOKUP(transactions_table8[[#This Row],[market_code]],markets_table!$A:$C,3,0) -> North | K8: =VLOOKUP(transactions_table8[[#This Row],[customer_code]],customer_table!$A:$B,2,0) -> Premium Stores | L8: =VLOOKUP(transactions_table8[[#This Row],[customer_code]],customer_table!$A:$C,3,0) -> Brick & Mortar | M8: =IF(TRIM(CLEAN(transactions_table8[[#This Row],[currency]]))="USD",transactions_table8[[#This Row],[sales_amount]]*83,transactions_table8[[#This Row],[sales_amount]]) -> 21412
A9: Prod003 | B9: Cus005 | C9: Mark004 | D9: 43066 | E9: 35 | F9: 19213 | G9: INR | H9: =VLOOKUP(A9, product_table!$A:$C, 3, 0) -> Own Brand | I9: =VLOOKUP(transactions_table8[[#This Row],[market_code]],markets_table!$A:$B,2,0) -> Delhi NCR | J9: =VLOOKUP(transactions_table8[[#This Row],[market_code]],markets_table!$A:$C,3,0) -> North | K9: =VLOOKUP(transactions_table8[[#This Row],[customer_code]],customer_table!$A:$B,2,0) -> Premium Stores | L9: =VLOOKUP(transactions_table8[[#This Row],[customer_code]],customer_table!$A:$C,3,0) -> Brick & Mortar | M9: =IF(TRIM(CLEAN(transactions_table8[[#This Row],[currency]]))="USD",transactions_table8[[#This Row],[sales_amount]]*83,transactions_table8[[#This Row],[sales_amount]]) -> 19213
A10: Prod003 | B10: Cus005 | C10: Mark004 | D10: 43067 | E10: 310 | F10: 170185 | G10: INR | H10: =VLOOKUP(A10, product_table!$A:$C, 3, 0) -> Own Brand | I10: =VLOOKUP(transactions_table8[[#This Row],[market_code]],markets_table!$A:$B,2,0) -> Delhi NCR | J10: =VLOOKUP(transactions_table8[[#This Row],[market_code]],markets_table!$A:$C,3,0) -> North | K10: =VLOOKUP(transactions_table8[[#This Row],[customer_code]],customer_table!$A:$B,2,0) -> Premium Stores | L10: =VLOOKUP(transactions_table8[[#This Row],[customer_code]],customer_table!$A:$C,3,0) -> Brick & Mortar | M10: =IF(TRIM(CLEAN(transactions_table8[[#This Row],[currency]]))="USD",transactions_table8[[#This Row],[sales_amount]]*83,transactions_table8[[#This Row],[sales_amount]]) -> 170185
A11: Prod003 | B11: Cus005 | C11: Mark004 | D11: 43068 | E11: 184 | F11: 101194 | G11: INR | H11: =VLOOKUP(A11, product_table!$A:$C, 3, 0) -> Own Brand | I11: =VLOOKUP(transactions_table8[[#This Row],[market_code]],markets_table!$A:$B,2,0) -> Delhi NCR | J11: =VLOOKUP(transactions_table8[[#This Row],[market_code]],markets_table!$A:$C,3,0) -> North | K11: =VLOOKUP(transactions_table8[[#This Row],[customer_code]],customer_table!$A:$B,2,0) -> Premium Stores | L11: =VLOOKUP(transactions_table8[[#This Row],[customer_code]],customer_table!$A:$C,3,0) -> Brick & Mortar | M11: =IF(TRIM(CLEAN(transactions_table8[[#This Row],[currency]]))="USD",transactions_table8[[#This Row],[sales_amount]]*83,transactions_table8[[#This Row],[sales_amount]]) -> 101194
A12: Prod003 | B12: Cus005 | C12: Mark004 | D12: 43069 | E12: 35 | F12: 19213 | G12: INR | H12: =VLOOKUP(A12, product_table!$A:$C, 3, 0) -> Own Brand | I12: =VLOOKUP(transactions_table8[[#This Row],[market_code]],markets_table!$A:$B,2,0) -> Delhi NCR | J12: =VLOOKUP(transactions_table8[[#This Row],[market_code]],markets_table!$A:$C,3,0) -> North | K12: =VLOOKUP(transactions_table8[[#This Row],[customer_code]],customer_table!$A:$B,2,0) -> Premium Stores | L12: =VLOOKUP(transactions_table8[[#This Row],[customer_code]],customer_table!$A:$C,3,0) -> Brick & Mortar | M12: =IF(TRIM(CLEAN(transactions_table8[[#This Row],[currency]]))="USD",transactions_table8[[#This Row],[sales_amount]]*83,transactions_table8[[#This Row],[sales_amount]]) -> 19213
A13: Prod004 | B13: Cus005 | C13: Mark004 | D13: 43068 | E13: 17 | F13: 9426 | G13: INR | H13: =VLOOKUP(A13, product_table!$A:$C, 3, 0) -> Own Brand | I13: =VLOOKUP(transactions_table8[[#This Row],[market_code]],markets_table!$A:$B,2,0) -> Delhi NCR | J13: =VLOOKUP(transactions_table8[[#This Row],[market_code]],markets_table!$A:$C,3,0) -> North | K13: =VLOOKUP(transactions_table8[[#This Row],[customer_code]],customer_table!$A:$B,2,0) -> Premium Stores | L13: =VLOOKUP(transactions_table8[[#This Row],[customer_code]],customer_table!$A:$C,3,0) -> Brick & Mortar | M13: =IF(TRIM(CLEAN(transactions_table8[[#This Row],[currency]]))="USD",transactions_table8[[#This Row],[sales_amount]]*83,transactions_table8[[#This Row],[sales_amount]]) -> 9426
... A992: Prod018 | B992: Cus025 | C992: Mark002 | D992: 43514 | E992: 8 | F992: 17495 | G992: INR_x000D_ | H992: =VLOOKUP(A992, product_table!$A:$C, 3, 0) -> Own Brand | I992: =VLOOKUP(transactions_table8[[#This Row],[market_code]],markets_table!$A:$B,2,0) -> Mumbai | J992: =VLOOKUP(transactions_table8[[#This Row],[market_code]],markets_table!$A:$C,3,0) -> Central | K992: =VLOOKUP(transactions_table8[[#This Row],[customer_code]],customer_table!$A:$B,2,0) -> Path | L992: =VLOOKUP(transactions_table8[[#This Row],[customer_code]],customer_table!$A:$C,3,0) -> E-Commerce | M992: =IF(TRIM(CLEAN(transactions_table8[[#This Row],[currency]]))="USD",transactions_table8[[#This Row],[sales_amount]]*83,transactions_table8[[#This Row],[sales_amount]]) -> 17495

Sheet pivots
A3: Sum of sales_amount
A4: 12779476
A7: Row Labels | B7: Sum of sales_amount
A8: Ahmedabad | B8: 1027488
A9: Bhopal | B9: 88388
A10: Chennai | B10: 485083
A11: Delhi NCR | B11: 4098717
A12: Kanpur | B12: 434883
A13: Lucknow | B13: 105333
A14: Mumbai | B14: 6539584
A15: Grand Total | B15: 12779476
A21: Row Labels | B21: Sum of sales_amount
A22: Electricalsara Stores | B22: 2359181
A23: Electricalslytical | B23: 2289335
A24: Info Stores | B24: 966470
A25: Logic Stores | B25: 1819465
A26: Path | B26: 1883686
A27: Grand Total | B27: 9318137
A32: Row Labels | B32: Sum of sales_amount
A33: Brick & Mortar | B33: 7562329
A34: E-Commerce | B34: 5217147
A35: Grand Total | B35: 12779476
A40: Row Labels | B40: Sum of sales_amount
A41: Prod001 | B41: 82482
A42: Prod002 | B42: 17268
A43: Prod003 | B43: 724546
A44: Prod004 | B44: 59852
A45: Prod005 | B45: 1265146
A46: Prod006 | B46: 10100
A47: Prod007 | B47: 12436
A48: Prod008 | B48: 35408
A49: Prod009 | B49: 131160
A50: Prod010 | B50: 295006
A51: Prod011 | B51: 410060
A52: Prod012 | B52: 59296
... A59: Grand Total | B59: 12779476
A62: Row Labels | B62: Sum of sales_amount
A63: 2017 | B63: 1773609
A64: 2018 | B64: 7687469
A65: 2019 | B65: 3296370
...
